<?xml version="1.0"?>
<robot name="my_box_bot">
    <!-- Links -->
    <link name="base_link"/>

    <link name="chassis">
        <visual>
        <origin rpy="0 0 0" xyz="0 0 0" />
        <geometry>
            <box size="0.1 0.1 0.1"/>
        </geometry>
        <material name="blue">
            <color rgba="0.0 0.0 1.0 1"/>
        </material>
        </visual>
    </link>

    <link name="left_wheel">
        <visual>
        <origin rpy="1.5707 0 0" xyz="0 0 0" />
        <geometry>
            <cylinder length="0.001" radius="0.035"/>
        </geometry>
        <material name="white">
            <color rgba="1.0 1.0 1.0 1"/>
        </material>
        </visual>
    </link>

    <link name="right_wheel">
        <visual>
        <origin rpy="1.5707 0 0" xyz="0 0 0" />
        <geometry>
            <cylinder length="0.001" radius="0.035"/>
        </geometry>
        <material name="black">
            <color rgba="0.0 0.0 0.0 1"/>
        </material>
        </visual>
    </link>

    <link name="front_yaw_link">
        <visual>
        <origin rpy="0 0 0" xyz="0 0 0" />
        <geometry>
            <cylinder length="0.005" radius="0.010"/>
        </geometry>
        <material name="blue">
            <color rgba="0.0 0.0 1.0 1"/>
        </material>
        </visual>
    </link>

    <link name="back_yaw_link">
        <visual>
        <origin rpy="0 0 0" xyz="0 0 0" />
        <geometry>
            <cylinder length="0.005" radius="0.010"/>
        </geometry>
        <material name="blue">
            <color rgba="0.0 0.0 1.0 1"/>
        </material>
        </visual>
    </link>

    <link name="front_roll_link">
        <visual>
        <origin rpy="0 0 0" xyz="0 0 0" />
        <geometry>
            <cylinder length="0.005" radius="0.010"/>
        </geometry>
        <material name="red">
            <color rgba="1.0 0.0 0.0 1"/>
        </material>
        </visual>
    </link> 

    <link name="back_roll_link">
        <visual>
        <origin rpy="0 0 0" xyz="0 0 0" />
        <geometry>
            <cylinder length="0.005" radius="0.010"/>
        </geometry>
        <material name="red">
            <color rgba="1.0 0.0 0.0 1"/>
        </material>
        </visual>
    </link> 

    <link name="front_pitch_link">
        <visual>
        <origin rpy="0 0 0" xyz="0 0 0" />
        <geometry>
            <sphere radius="0.010"/>
        </geometry>
        <material name="green_dark">
            <color rgba="0.0 0.5 0.0 1"/>
        </material>
        </visual>
    </link>

    <link name="back_pitch_link">
        <visual>
        <origin rpy="0 0 0" xyz="0 0 0" />
        <geometry>
            <sphere radius="0.010"/>
        </geometry>
          <material name="green_light">
            <color rgba="0.0 1.0 0.0 1"/>
        </material>
        </visual>
    </link> 

    <!-- Joints -->
    <joint name="base_link_joint" type="fixed">
        <origin rpy="0 0 0" xyz="0 0 0" />
        <child link="chassis" />
        <parent link="base_link" />
    </joint>

    <joint name="joint_left_wheel" type="continuous">
        <origin rpy="0 0 0" xyz="0 0.05 -0.025" />
        <child link="left_wheel" />
        <parent link="chassis" />
    </joint>

    <joint name="joint_right_wheel" type="continuous">
        <origin rpy="0 0 0" xyz="0 -0.05 -0.025" />
        <child link="right_wheel" />
        <parent link="chassis" />
    </joint>

    <joint name="back_yaw_joint" type="continuous">
        <origin rpy="0 0 0" xyz="-0.04 0 -0.05" />
        <child link="back_yaw_link" />
        <parent link="chassis" />
    </joint>

    <joint name="front_yaw_joint" type="continuous">
        <origin rpy="0 0 0" xyz="0.04 0 -0.05" />
        <child link="front_yaw_link" />
        <parent link="chassis" />
    </joint>
    
    <joint name="back_roll_joint" type="continuous">
        <origin  rpy="0 0 0" xyz="0 0 0" />
        <child link="back_roll_link" />
        <parent link="back_yaw_link" />
    </joint>
    
    <joint name="front_roll_joint" type="continuous">
        <origin  rpy="0 0 0" xyz="0 0 0" />
        <child link="front_roll_link" />
        <parent link="front_yaw_link" />
    </joint>
    
    <joint name="back_pitch_joint" type="continuous">
        <origin  rpy="0 0 0" xyz="0 0 0" />
        <child link="back_pitch_link" />
        <parent link="back_roll_link" />
    </joint>
    
    <joint name="front_pitch_joint" type="continuous">
        <origin  rpy="0 0 0" xyz="0 0 0" />
        <child link="front_pitch_link" />
        <parent link="front_roll_link" />
    </joint>
</robot>